Workbook

Sheet Data
A1: Participant | B1: Set Size | C1: clicked | D1: RT (s) | E1: accurate | F1: RT(ms) | I1: num_distr | J1: num_distra
A2: 1 | B2: =IF(I2<>"",I2,J2) -> 10 | C2: target' | D2: 1.4751871 | E2: =IF(ISNUMBER(SEARCH("target",#REF!)),1,0) -> 0 | F2: =D2*1000 -> 1475.1871 | J2: 10
A3: 1 | B3: =IF(I3<>"",I3,J3) -> 5 | C3: target' | D3: 1.0510162 | E3: =IF(ISNUMBER(SEARCH("target",C2)),1,0) -> 1 | F3: =D3*1000 -> 1051.0162 | I3: 5
A4: 1 | B4: =IF(I4<>"",I4,J4) -> 5 | C4: target' | D4: 1.0579192 | E4: =IF(ISNUMBER(SEARCH("target",C3)),1,0) -> 1 | F4: =D4*1000 -> 1057.9192 | I4: 5
A5: 1 | B5: =IF(I5<>"",I5,J5) -> 5 | C5: target' | D5: 0.8745299 | E5: =IF(ISNUMBER(SEARCH("target",C4)),1,0) -> 1 | F5: =D5*1000 -> 874.5299 | I5: 5
A6: 1 | B6: =IF(I6<>"",I6,J6) -> 10 | C6: target' | D6: 1.3676817 | E6: =IF(ISNUMBER(SEARCH("target",C5)),1,0) -> 1 | F6: =D6*1000 -> 1367.6817 | J6: 10
A7: 1 | B7: =IF(I7<>"",I7,J7) -> 5 | C7: target' | D7: 1.0429107 | E7: =IF(ISNUMBER(SEARCH("target",C6)),1,0) -> 1 | F7: =D7*1000 -> 1042.9107 | I7: 5
A8: 1 | B8: =IF(I8<>"",I8,J8) -> 10 | C8: None | D8: 1.0315682 | E8: =IF(ISNUMBER(SEARCH("target",C7)),1,0) -> 1 | F8: =D8*1000 -> 1031.5682 | J8: 10
A9: 1 | B9: =IF(I9<>"",I9,J9) -> 10 | C9: None | D9: 1.0815025 | E9: =IF(ISNUMBER(SEARCH("target",C8)),1,0) -> 0 | F9: =D9*1000 -> 1081.5025 | J9: 10
A10: 1 | B10: =IF(I10<>"",I10,J10) -> 10 | C10: None | D10: 0.9666912 | E10: =IF(ISNUMBER(SEARCH("target",C9)),1,0) -> 0 | F10: =D10*1000 -> 966.6912 | J10: 10
A11: 1 | B11: =IF(I11<>"",I11,J11) -> 10 | C11: target' | D11: 1.2309631 | E11: =IF(ISNUMBER(SEARCH("target",C10)),1,0) -> 0 | F11: =D11*1000 -> 1230.9631 | J11: 10
A12: 1 | B12: =IF(I12<>"",I12,J12) -> 5 | C12: target' | D12: 0.7749937 | E12: =IF(ISNUMBER(SEARCH("target",C11)),1,0) -> 1 | F12: =D12*1000 -> 774.9937 | I12: 5
A13: 1 | B13: =IF(I13<>"",I13,J13) -> 10 | C13: target' | D13: 0.6967793 | E13: =IF(ISNUMBER(SEARCH("target",C12)),1,0) -> 1 | F13: =D13*1000 -> 696.7793 | J13: 10
A14: 1 | B14: =IF(I14<>"",I14,J14) -> 10 | C14: target' | D14: 0.9871957 | E14: =IF(ISNUMBER(SEARCH("target",C13)),1,0) -> 1 | F14: =D14*1000 -> 987.1957 | J14: 10
A15: 1 | B15: =IF(I15<>"",I15,J15) -> 5 | C15: target' | D15: 0.9000112 | E15: =IF(ISNUMBER(SEARCH("target",C14)),1,0) -> 1 | F15: =D15*1000 -> 900.0112 | I15: 5
A16: 1 | B16: =IF(I16<>"",I16,J16) -> 10 | C16: None | D16: 0.9300424 | E16: =IF(ISNUMBER(SEARCH("target",C15)),1,0) -> 1 | F16: =D16*1000 -> 930.0424 | J16: 10
A17: 1 | B17: =IF(I17<>"",I17,J17) -> 10 | C17: target' | D17: 1.0678028 | E17: =IF(ISNUMBER(SEARCH("target",C16)),1,0) -> 0 | F17: =D17*1000 -> 1067.8028 | J17: 10
A18: 1 | B18: =IF(I18<>"",I18,J18) -> 10 | C18: target' | D18: 1.3180102 | E18: =IF(ISNUMBER(SEARCH("target",C17)),1,0) -> 1 | F18: =D18*1000 -> 1318.0102 | J18: 10
A19: 1 | B19: =IF(I19<>"",I19,J19) -> 5 | C19: None | D19: 0.8227388 | E19: =IF(ISNUMBER(SEARCH("target",C18)),1,0) -> 1 | F19: =D19*1000 -> 822.7388 | I19: 5
A20: 1 | B20: =IF(I20<>"",I20,J20) -> 10 | C20: None | D20: 0.6666234 | E20: =IF(ISNUMBER(SEARCH("target",C19)),1,0) -> 0 | F20: =D20*1000 -> 666.6234 | J20: 10
A21: 1 | B21: =IF(I21<>"",I21,J21) -> 5 | C21: None | D21: 0.8597544 | E21: =IF(ISNUMBER(SEARCH("target",C20)),1,0) -> 0 | F21: =D21*1000 -> 859.7544 | I21: 5
A22: 1 | B22: =IF(I22<>"",I22,J22) -> 5 | C22: target' | D22: 1.1058332 | E22: =IF(ISNUMBER(SEARCH("target",C21)),1,0) -> 0 | F22: =D22*1000 -> 1105.8332 | I22: 5
A23: 1 | B23: =IF(I23<>"",I23,J23) -> 10 | C23: None | D23: 0.950545 | E23: =IF(ISNUMBER(SEARCH("target",C22)),1,0) -> 1 | F23: =D23*1000 -> 950.545 | J23: 10
A24: 1 | B24: =IF(I24<>"",I24,J24) -> 5 | C24: target' | D24: 0.775097 | E24: =IF(ISNUMBER(SEARCH("target",C23)),1,0) -> 0 | F24: =D24*1000 -> 775.097 | I24: 5
A25: 1 | B25: =IF(I25<>"",I25,J25) -> 10 | C25: None | D25: 1.0182404 | E25: =IF(ISNUMBER(SEARCH("target",C24)),1,0) -> 1 | F25: =D25*1000 -> 1018.2404 | J25: 10
A26: 1 | B26: =IF(I26<>"",I26,J26) -> 10 | C26: target' | D26: 0.9666434 | E26: =IF(ISNUMBER(SEARCH("target",C25)),1,0) -> 0 | F26: =D26*1000 -> 966.6434 | J26: 10
A27: 1 | B27: =IF(I27<>"",I27,J27) -> 10 | C27: target' | D27: 0.9849491 | E27: =IF(ISNUMBER(SEARCH("target",C26)),1,0) -> 1 | F27: =D27*1000 -> 984.9491 | J27: 10
A28: 1 | B28: =IF(I28<>"",I28,J28) -> 5 | C28: None | D28: 1.1068556 | E28: =IF(ISNUMBER(SEARCH("target",C27)),1,0) -> 1 | F28: =D28*1000 -> 1106.8556 | I28: 5
A29: 1 | B29: =IF(I29<>"",I29,J29) -> 10 | C29: None | D29: 1.3498345 | E29: =IF(ISNUMBER(SEARCH("target",C28)),1,0) -> 0 | F29: =D29*1000 -> 1349.8345 | J29: 10
A30: 1 | B30: =IF(I30<>"",I30,J30) -> 5 | C30: target' | D30: 0.8092288 | E30: =IF(ISNUMBER(SEARCH("target",C29)),1,0) -> 0 | F30: =D30*1000 -> 809.2288 | I30: 5
A31: 1 | B31: =IF(I31<>"",I31,J31) -> 10 | C31: target' | D31: 0.7683131 | E31: =IF(ISNUMBER(SEARCH("target",C30)),1,0) -> 1 | F31: =D31*1000 -> 768.3131 | J31: 10
A32: 1 | B32: =IF(I32<>"",I32,J32) -> 10 | C32: target' | D32: 0.9843729 | E32: =IF(ISNUMBER(SEARCH("target",C31)),1,0) -> 1 | F32: =D32*1000 -> 984.3729 | J32: 10
A33: 1 | B33: =IF(I33<>"",I33,J33) -> 10 | C33: target' | D33: 1.2529875 | E33: =IF(ISNUMBER(SEARCH("target",C32)),1,0) -> 1 | F33: =D33*1000 -> 1252.9875 | J33: 10
A34: 1 | B34: =IF(I34<>"",I34,J34) -> 5 | C34: target' | D34: 1.1592676 | E34: =IF(ISNUMBER(SEARCH("target",C33)),1,0) -> 1 | F34: =D34*1000 -> 1159.2676 | I34: 5
A35: 1 | B35: =IF(I35<>"",I35,J35) -> 10 | C35: target' | D35: 0.7850996 | E35: =IF(ISNUMBER(SEARCH("target",C34)),1,0) -> 1 | F35: =D35*1000 -> 785.0996 | J35: 10
A36: 1 | B36: =IF(I36<>"",I36,J36) -> 5 | C36: None | D36: 0.9924866 | E36: =IF(ISNUMBER(SEARCH("target",C35)),1,0) -> 1 | F36: =D36*1000 -> 992.4866 | I36: 5
A37: 1 | B37: =IF(I37<>"",I37,J37) -> 5 | C37: target' | D37: 1.2404815 | E37: =IF(ISNUMBER(SEARCH("target",C36)),1,0) -> 0 | F37: =D37*1000 -> 1240.4815 | I37: 5
A38: 1 | B38: =IF(I38<>"",I38,J38) -> 5 | C38: target' | D38: 1.0082333 | E38: =IF(ISNUMBER(SEARCH("target",C37)),1,0) -> 1 | F38: =D38*1000 -> 1008.2333 | I38: 5
A39: 1 | B39: =IF(I39<>"",I39,J39) -> 10 | C39: None | D39: 1.0004953 | E39: =IF(ISNUMBER(SEARCH("target",C38)),1,0) -> 1 | F39: =D39*1000 -> 1000.4953 | J39: 10
A40: 1 | B40: =IF(I40<>"",I40,J40) -> 5 | C40: None | D40: 1.1598721 | E40: =IF(ISNUMBER(SEARCH("target",C39)),1,0) -> 0 | F40: =D40*1000 -> 1159.8721 | I40: 5
...

Sheet Analysis
A1: Participant | B1: Mean RT set size 5 (ms) | C1: Mean RT set size 10 (ms) | D1: Mean RT all accurate trials (ms) | E1: Slope (ms per item) | G1: Set Size | H1: Mean RT(ms)
A2: 1 | B2: =AVERAGEIFS(Data!$F$2:$F$1001,Data!$A$2:$A$1001,$A2,Data!$B$2:$B$1001,5,Data!$E$2:$E$1001,1) -> 1023.1577 | C2: =AVERAGEIFS(Data!$F$2:$F$1001,Data!$A$2:$A$1001,$A2,Data!$B$2:$B$1001,10,Data!$E$2:$E$1001,1) -> 961.78298 | D2: =AVERAGEIFS(Data!$F$2:$F$1001,Data!$A$2:$A$1001,$A2,Data!$E$2:$E$1001,1) -> 990.56934 | E2: =(C2-B2)/5 -> -12.274939 | G2: Set Size 5 | H2: =B7 -> 1451.6342
A3: 2 | B3: =AVERAGEIFS(Data!$F$2:$F$1001,Data!$A$2:$A$1001,$A3,Data!$B$2:$B$1001,5,Data!$E$2:$E$1001,1) -> 1374.0931 | C3: =AVERAGEIFS(Data!$F$2:$F$1001,Data!$A$2:$A$1001,$A3,Data!$B$2:$B$1001,10,Data!$E$2:$E$1001,1) -> 1324.753 | D3: =AVERAGEIFS(Data!$F$2:$F$1001,Data!$A$2:$A$1001,$A3,Data!$E$2:$E$1001,1) -> 1345.6122 | E3: =(C3-B3)/5 -> -9.8680346 | G3: Set Size 10 | H3: =C7 -> 1420.4066
A4: 3 | B4: =AVERAGEIFS(Data!$F$2:$F$1001,Data!$A$2:$A$1001,$A4,Data!$B$2:$B$1001,5,Data!$E$2:$E$1001,1) -> 1813.1557 | C4: =AVERAGEIFS(Data!$F$2:$F$1001,Data!$A$2:$A$1001,$A4,Data!$B$2:$B$1001,10,Data!$E$2:$E$1001,1) -> 1680.3523 | D4: =AVERAGEIFS(Data!$F$2:$F$1001,Data!$A$2:$A$1001,$A4,Data!$E$2:$E$1001,1) -> 1741.0027 | E4: =(C4-B4)/5 -> -26.560665
A5: 4 | B5: =AVERAGEIFS(Data!$F$2:$F$1001,Data!$A$2:$A$1001,$A5,Data!$B$2:$B$1001,5,Data!$E$2:$E$1001,1) -> 1389.202 | C5: =AVERAGEIFS(Data!$F$2:$F$1001,Data!$A$2:$A$1001,$A5,Data!$B$2:$B$1001,10,Data!$E$2:$E$1001,1) -> 1368.8964 | D5: =AVERAGEIFS(Data!$F$2:$F$1001,Data!$A$2:$A$1001,$A5,Data!$E$2:$E$1001,1) -> 1378.452 | E5: =(C5-B5)/5 -> -4.061116
A6: 5 | B6: =AVERAGEIFS(Data!$F$2:$F$1001,Data!$A$2:$A$1001,$A6,Data!$B$2:$B$1001,5,Data!$E$2:$E$1001,1) -> 1658.5624 | C6: =AVERAGEIFS(Data!$F$2:$F$1001,Data!$A$2:$A$1001,$A6,Data!$B$2:$B$1001,10,Data!$E$2:$E$1001,1) -> 1766.2481 | D6: =AVERAGEIFS(Data!$F$2:$F$1001,Data!$A$2:$A$1001,$A6,Data!$E$2:$E$1001,1) -> 1711.0067 | E6: =(C6-B6)/5 -> 21.537129
A7: Mean | B7: =AVERAGE(B2:B6) -> 1451.6342 | C7: =AVERAGE(C2:C6) -> 1420.4066 | D7: =AVERAGE(D2:D6) -> 1433.3286 | E7: =AVERAGE(E2:E6) -> -6.2455249
